Traceback (most recent call last):
  File "/Library/Frameworks/Python.framework/Versions/3.10/lib/python3.10/site-packages/jupyter_cache/executors/utils.py", line 58, in single_nb_execution
    executenb(
  File "/Users/belka/Library/Python/3.10/lib/python/site-packages/nbclient/client.py", line 1265, in execute
    return NotebookClient(nb=nb, resources=resources, km=km, **kwargs).execute()
  File "/Users/belka/Library/Python/3.10/lib/python/site-packages/jupyter_core/utils/__init__.py", line 166, in wrapped
    return loop.run_until_complete(inner)
  File "/Library/Frameworks/Python.framework/Versions/3.10/lib/python3.10/asyncio/base_events.py", line 646, in run_until_complete
    return future.result()
  File "/Users/belka/Library/Python/3.10/lib/python/site-packages/nbclient/client.py", line 703, in async_execute
    await self.async_execute_cell(
  File "/Users/belka/Library/Python/3.10/lib/python/site-packages/nbclient/client.py", line 1021, in async_execute_cell
    await self._check_raise_for_error(cell, cell_index, exec_reply)
  File "/Users/belka/Library/Python/3.10/lib/python/site-packages/nbclient/client.py", line 915, in _check_raise_for_error
    raise CellExecutionError.from_cell_and_msg(cell, exec_reply_content)
nbclient.exceptions.CellExecutionError: An error occurred while executing the following cell:
------------------
#Создадим точку - Сквер Низами

point_df = pd.DataFrame({"name": 'Сквер Низами', 'lat':59.963768, 'lon': 30.314455}, [1])
point_gdf_utm = gpd.GeoDataFrame(point_df, geometry=gpd.points_from_xy(point_df['lon'], point_df['lat']), crs=4326).to_crs(target_crs)


buffer_500_point = point_gdf_utm.buffer(800)
clipped_buildings = building_utm.clip(buffer_500_point)


clipped_buildings.explore(tiles='cartodbpositron')
------------------

[0;31m---------------------------------------------------------------------------[0m
[0;31mNameError[0m                                 Traceback (most recent call last)
Cell [0;32mIn[5], line 4[0m
[1;32m      1[0m [38;5;66;03m#Создадим точку - Сквер Низами[39;00m
[1;32m      3[0m point_df [38;5;241m=[39m pd[38;5;241m.[39mDataFrame({[38;5;124m"[39m[38;5;124mname[39m[38;5;124m"[39m: [38;5;124m'[39m[38;5;124mСквер Низами[39m[38;5;124m'[39m, [38;5;124m'[39m[38;5;124mlat[39m[38;5;124m'[39m:[38;5;241m59.963768[39m, [38;5;124m'[39m[38;5;124mlon[39m[38;5;124m'[39m: [38;5;241m30.314455[39m}, [[38;5;241m1[39m])
[0;32m----> 4[0m point_gdf_utm [38;5;241m=[39m gpd[38;5;241m.[39mGeoDataFrame(point_df, geometry[38;5;241m=[39mgpd[38;5;241m.[39mpoints_from_xy(point_df[[38;5;124m'[39m[38;5;124mlon[39m[38;5;124m'[39m], point_df[[38;5;124m'[39m[38;5;124mlat[39m[38;5;124m'[39m]), crs[38;5;241m=[39m[38;5;241m4326[39m)[38;5;241m.[39mto_crs([43mtarget_crs[49m)
[1;32m      7[0m buffer_500_point [38;5;241m=[39m point_gdf_utm[38;5;241m.[39mbuffer([38;5;241m800[39m)
[1;32m      8[0m clipped_buildings [38;5;241m=[39m building_utm[38;5;241m.[39mclip(buffer_500_point)

[0;31mNameError[0m: name 'target_crs' is not defined
NameError: name 'target_crs' is not defined

