Traceback (most recent call last):
  File "/Library/Frameworks/Python.framework/Versions/3.10/lib/python3.10/site-packages/jupyter_cache/executors/utils.py", line 58, in single_nb_execution
    executenb(
  File "/Users/belka/Library/Python/3.10/lib/python/site-packages/nbclient/client.py", line 1265, in execute
    return NotebookClient(nb=nb, resources=resources, km=km, **kwargs).execute()
  File "/Users/belka/Library/Python/3.10/lib/python/site-packages/jupyter_core/utils/__init__.py", line 166, in wrapped
    return loop.run_until_complete(inner)
  File "/Library/Frameworks/Python.framework/Versions/3.10/lib/python3.10/asyncio/base_events.py", line 646, in run_until_complete
    return future.result()
  File "/Users/belka/Library/Python/3.10/lib/python/site-packages/nbclient/client.py", line 703, in async_execute
    await self.async_execute_cell(
  File "/Users/belka/Library/Python/3.10/lib/python/site-packages/nbclient/client.py", line 1021, in async_execute_cell
    await self._check_raise_for_error(cell, cell_index, exec_reply)
  File "/Users/belka/Library/Python/3.10/lib/python/site-packages/nbclient/client.py", line 915, in _check_raise_for_error
    raise CellExecutionError.from_cell_and_msg(cell, exec_reply_content)
nbclient.exceptions.CellExecutionError: An error occurred while executing the following cell:
------------------
# Ссылка на данные WorldPop
url = "https://data.worldpop.org/GIS/Population/Global_2000_2020_Constrained/2020/BSGM/RUS/rus_ppp_2020_constrained.tif"

# Имя файла для сохранения
output_file = "worldpop_russia_2020.tif"

# Скачивание файла
response = requests.get(url, stream=True)

if response.status_code == 200:
    with open(output_file, "wb") as file:
        for chunk in response.iter_content(chunk_size=1024):
            file.write(chunk)
    print(f"File saved as {output_file}")
else:
    print("Failed to download file. Status code:", response.status_code)

------------------

[0;31m---------------------------------------------------------------------------[0m
[0;31mNameError[0m                                 Traceback (most recent call last)
Cell [0;32mIn[1], line 8[0m
[1;32m      5[0m output_file [38;5;241m=[39m [38;5;124m"[39m[38;5;124mworldpop_russia_2020.tif[39m[38;5;124m"[39m
[1;32m      7[0m [38;5;66;03m# Скачивание файла[39;00m
[0;32m----> 8[0m response [38;5;241m=[39m [43mrequests[49m[38;5;241m.[39mget(url, stream[38;5;241m=[39m[38;5;28;01mTrue[39;00m)
[1;32m     10[0m [38;5;28;01mif[39;00m response[38;5;241m.[39mstatus_code [38;5;241m==[39m [38;5;241m200[39m:
[1;32m     11[0m     [38;5;28;01mwith[39;00m [38;5;28mopen[39m(output_file, [38;5;124m"[39m[38;5;124mwb[39m[38;5;124m"[39m) [38;5;28;01mas[39;00m file:

[0;31mNameError[0m: name 'requests' is not defined
NameError: name 'requests' is not defined

